Workbook

Sheet General information
A1: General Information
A2: Company name and legal form | B2: No-ProfitName LegalForm
A3: The domicile | B3: Address 1234, Country
A4: Country of incorporation | B4: Country
A5: Address of entity's registered office | B5: Addres 1234
A6: Name of the reporting entity | B6: No-ProfitNameReporting, department Accountacy
A7: Principal place of business | B7: Address 12345, Country A
A8: Start period | B8: 45292
A9: End period | B9: 45657
A10: Description of nature of entity's operations and principal activities | B10: Description of nature of entity's operation and activities (Activity A, B, C, D)
A17: During the financial year the principal continuing activities of the company | B17: Activity A
B18: Activity B
B19: Activity C
B20: Activity D
A21: Currency | B21: EUR
A22: Contents | B22: Statement of Financial Position
B23: Statement of Income and Expenses
B24: Statement of Changes in Net Assets
B25: Statement of Cash Flows - indirect
B26: Notes of Statement of Financial Position
B27: Notes of Statement of Income and Expenses
B28: Notes of Statement of Cash Flows

Sheet Statement of Financial Position
A1: Identifying information of no-profit
A2: Company name and legal form | B2: ='General information'!B2 -> No-ProfitName LegalForm
A3: The domicile | B3: ='General information'!B3 -> Address 1234, Country
A4: Start period | B4: ='General information'!B8 -> 45292
A5: End period | B5: ='General information'!B9 -> 45657
A6: Statement of Financial Position
A9: Account | B9: ASSETS | C9: Notes | D9: =$B$4-1 -> 45291 | E9: =$B$5 -> 45657
B10: Non current Assets
A11: Investment | B11: Investment in associate | C11: 1 | D11: 0 | E11: 0
A12: Property | B12: Property, plant and equipment | C12: 2 | D12: 0 | E12: ='Notes of Financial Statement'!C48 -> 0
A13: Intangible Assets | B13: Intangible assets | C13: 3 | D13: 0 | E13: 0
A14: Deferred Tax Asset | B14: Deferred tax asset | C14: 4 | D14: 0 | E14: 0
B15: Total non-current assets | D15: =SUM(D11:D14) -> 0 | E15: =SUM(E11:E14) -> 0
B17: Current Assets
A18: Cash | B18: Cash | C18: 5 | D18: 0 | E18: 0
A19: Bank | B19: Bank | C19: 6 | D19: 0 | E19: 0
A20: Receivables | B20: Receivables | C20: 7 | D20: 0 | E20: 0
A21: Inventories | B21: Inventories | C21: 8 | D21: 0 | E21: 0
B22: Total current assets | D22: =SUM(D18:D21) -> 0 | E22: =SUM(E18:E21) -> 0
B23: TOTAL ASSETS | D23: =SUM(D15,D22) -> 0 | E23: =SUM(E15,E22) -> 0
A25: Account | B25: EQUITY AND LIABILITIES | C25: Notes | D25: =$B$4-1 -> 45291 | E25: =$B$5 -> 45657
B26: Net Assets
A27: Restricted Funds Project 1 | B27: Restricted Funds Project 1 | C27: 9 | D27: 0 | E27: 0
A28: Restricted Funds Project 2 | B28: Restricted Funds Project 2 | C28: 10 | D28: 0 | E28: 0
A29: Restricted Funds Project 3 | B29: Restricted Funds Project 3 | C29: 11 | D29: 0 | E29: 0
A30: Unrestricted Funds | B30: Funds without restrictions | C30: 12 | D30: 0 | E30: 0
A31: Equity | B31: Equity | C31: 13 | D31: 0 | E31: 0
A32: Non-controlling Int | B32: Non-controlling interests | C32: 14 | D32: 0 | E32: 0
B33: Total Net Assets | D33: =SUM(D27:D32) -> 0 | E33: =SUM(E27:E32) -> 0
B35: Non-current liabilities
A36: Loans | B36: Loans | C36: 15 | D36: 0 | E36: 0
A37: LT Emp Benefit Oblig | B37: Long-term employee benefit obligations | C37: 16 | D37: 0 | E37: 0
A38: Lease Oblig | B38: Obligations under finance leases | C38: 17 | D38: 0 | E38: 0
B39: Total non-current liabilities | D39: =SUM(D36:D38) -> 0 | E39: =SUM(E36:E38) -> 0
B41: Current liabilities
A42: Bank Overdraft | B42: Bank overdraft | C42: 18 | D42: 0 | E42: 0
A43: Payables | B43: Payables | C43: 19 | D43: 0 | E43: 0
A44: Grant oblig. liability | B44: Liabilities for unfulfilled grant delivery obligations | C44: 20 | D44: 0 | E44: 0
A45: Interest Payable | B45: Interest payable | C45: 21 | D45: 0 | E45: 0
A46: Current Tax Liability | B46: Current tax liability | C46: 22 | D46: 0 | E46: 0
...

Sheet Statement of Income & Expenses
A1: Identifying information of no-profit
A2: Company name and legal form | B2: ='General information'!B2 -> No-ProfitName LegalForm
A3: The domicile | B3: ='General information'!B3 -> Address 1234, Country
A4: Start period | B4: ='General information'!B8 -> 45292
A5: End period | B5: ='General information'!B9 -> 45657
A6: Statement of Income and Expenses
A9: Account | B9: INCOME | C9: Notes | D9: =$B$4-1 -> 45291 | E9: =$B$5 -> 45657
A10: Grants unrestricted | B10: [+] Grants and donations unrestricted | C10: 25 | D10: 0 | E10: 0
A11: Grants restricted Project 1 | B11: [+] Grants and donations restricted Project 1 | C11: 26 | D11: 0 | E11: 0
A12: Grants restricted Project 2 | B12: [+] Grants and donations restricted Project 2 | C12: 27 | D12: 0 | E12: 0
A13: Grants restricted Project 3 | B13: [+] Grants and donations restricted Project 3 | C13: 28 | D13: 0 | E13: 0
A14: Government grants unrestricted | B14: [+] Government grants unrestricted | C14: 29 | D14: 0 | E14: 0
A15: Government grants restricted | B15: [+] Government grants restricted | C15: 30 | D15: 0 | E15: 0
A16: Non‑Curr Asset Grants | B16: [+] Grants for and donations of non‑current assets | C16: 31 | D16: 0 | E16: 0
A17: Sales | B17: [+] Sales of services and goods | C17: 32 | D17: 0 | E17: 0
A18: Interest Income | B18: [+] Interest income | C18: 33 | D18: 0 | E18: 0
A19: Other Income | B19: [+] Other income | C19: 34 | D19: 0 | E19: 0
B20: TOTAL INCOME | D20: =SUM(D10:D19) -> 0 | E20: =SUM(E10:E19) -> 0
A22: Account | B22: EXPENSES | C22: Notes | D22: =$B$4-1 -> 45291 | E22: =$B$5 -> 45657
A23: Expenses Project 1 | B23: [-] Expenses Project 1 | C23: 35 | D23: 0 | E23: 0
A24: Expenses Project 2 | B24: [-] Expenses Project 2 | C24: 36 | D24: 0 | E24: 0
A25: Expenses Project 3 | B25: [-] Expenses Project 3 | C25: 37 | D25: 0 | E25: 0
A26: Operating Expenses | B26: [-] Operating Expenses | C26: 38 | D26: 0 | E26: 0
A27: Depreciation | B27: [-] Depreciation and amortisation expenses | C27: 39 | D27: 0 | E27: 0
A28: Impairment Expenses | B28: [-] Impairment expenses | C28: 40 | D28: 0 | E28: 0
A29: Interest Expenses | B29: [-] Interest expenses | C29: 41 | D29: 0 | E29: 0
A30: Other Expenses | B30: [-] Other expenses | C30: 42 | D30: 0 | E30: 0
B31: TOTAL EXPENSES | D31: =SUM(D23:D30) -> 0 | E31: =SUM(E23:E30) -> 0
A33: Account | B33: Surplus or deficit from operating activities | C33: Notes | D33: =SUM(D20,D31) -> 0 | E33: =SUM(E20,E31) -> 0
A34: Assoc Surplus Share | B34: [+/-] Share of surplus of associates | C34: 43 | D34: 0 | E34: 0
A35: Asset Disposal Gain/Loss | B35: [+/-] Gain or loss on disposal of assets | C35: 44 | D35: 0 | E35: 0
A36: FX UnrealGain/Loss | B36: [+/-] Unrealised gains or losses on foreign exchange differences | C36: 45 | D36: 0 | E36: 0
A37: Defined Benefit Plans | B37: [+/-] Defined benefit plans | C37: 46 | D37: 0 | E37: 0
A38: Financial Instruments | B38: [+/-] Financial instruments | C38: 47 | D38: 0 | E38: 0
A39: Investment Property | B39: [+/-] Investment property | C39: 48 | D39: 0 | E39: 0
B40: Total other gains and losses | D40: =SUM($D34:$D39) -> 0 | E40: =SUM($E34:$E39) -> 0
B41: TOTAL SURPLUS OR DEFICIT | D41: =SUM(D33,D40) -> 0 | E41: =SUM(E33,E40) -> 0

Sheet Statement of Changes NetAssets
A1: Identifying information of no-profit
A2: Company name and legal form | B2: ='General information'!B2 -> No-ProfitName LegalForm
A3: The domicile | B3: ='General information'!B3 -> Address 1234, Country
A4: Start period | B4: ='General information'!B8 -> 45292
A5: End period | B5: ='General information'!B9 -> 45657
A6: Statement of Changes in Net Assets
A9: Code | B9: Net Assets | D9: =$B$4 -> 45292 | E9: =$B$5 -> 45657
A10: EQB | B10: Net Assets at beginning of period | D10: ='Statement of Financial Position'!D33 -> 0
A12: Code | B12: Surplus and movements recognised directly in net assets | D12: =$B$4 -> 45292 | E12: =$B$5 -> 45657
A13: PLE | B13: [+] Profit [-] Loss | E13: ='Statement of Income & Expenses'!E41 -> 0
A14: OCI | B14: Gains and losses recognised directly in net assets | E14: 0
B15: Total surplus and direct net asset movements | E15: =SUM(E13:E14) -> 0
A17: Code | B17: Other movements in net assets (excluding surplus) | D17: =$B$4 -> 45292 | E17: =$B$5 -> 45657
A18: RFP1 | B18: [+/-] Restricted Funds Project 1 | E18: 0
A19: RFP2 | B19: [+/-] Restricted Funds Project 2 | E19: 0
A20: RFP3 | B20: [+/-] Restricted Funds Project 3 | E20: 0
A21: FNR | B21: [+/-] Funds without restrictions | E21: 0
A22: NCI | B22: [+/-] Non-controlling interests | E22: 0
B23: Total other movements in net assets | E23: =SUM(E18:E22) -> 0
A25: EQE | B25: Net Assets at end of period | E25: =SUM(D10,E15,E23) -> 0

Sheet Cash Flows Statement - indirect
A1: Identifying information of no-profit
A2: Company name and legal form | B2: ='General information'!B2 -> No-ProfitName LegalForm
A3: The domicile | B3: ='General information'!B3 -> Address 1234, Country
A4: Start period | B4: ='General information'!B8 -> 45292
A5: End period | B5: ='General information'!B9 -> 45657
A6: Statement of Cash Flows, indirect method
A9: Code | B9: Profit or Loss | D9: Notes | E9: =$B$5 -> 45657
A10: PLC | B10: [+] Profit [-] Loss | E10: ='Statement of Income & Expenses'!E41 -> 0
A12: Code | B12: Net cash flows from operating activities | D12: Notes | E12: =$B$5 -> 45657
A13: DAE | B13: [+] Depreciation and amortisation expenses | E13: 0
A14: IE | B14: [+] Impairment expenses | E14: 0
A15: DPPE | B15: [-] Donations of PPE received in kind (non-cash) | E15: 0
A16: UGLFED | B16: [-/+] Unrealised foreign exchange gains/losses | E16: 0
A17: GLDA | B17: [-/+] Gain/loss on asset disposals (non-cash reversal) | E17: 0
A18: CG | B18: [+/-] Capital grant accrual adjustments | E18: 0
A19: SSA | B19: [+/-] Increase/decrease in inventories | E19: 0
A20: IDWIP | B20: [+/-] Increase/decrease in WIP | E20: 0
A21: IDOCA | B21: [+/-] Increase/decrease in other current assets | E21: 0
A22: IDOCL | B22: [+/-] Increase/decrease in other current liabilities | E22: 0
A23: IDOC | B23: [+/-] Increase/decrease in operational creditors | E23: 0
A24: IDA | B24: [+/-] Increase/decrease in accruals | E24: 0
B25: Net cash flows from operating activities | E25: =E10+SUM(E13:E24) -> 0
A27: Code | B27: Cash flows from investing activities | D27: Notes | E27: =$B$5 -> 45657
A28: APPE | B28: [-] Acquisition of PPE | E28: 0
A29: AIA | B29: [-] Acquisition of intangible assets | E29: 0
A30: RGPPE | B30: [+/-] Other investing cash flows | E30: 0
A31: DISP | B31: [+] Receipts from disposal of assets | E31: 0
B32: Net cash flows from investing activities | E32: =SUM(E28:E31) -> 0
A34: Code | B34: Cash flows from financing activities | D34: Notes | E34: =$B$5 -> 45657
A35: RBOR | B35: [-] Repayment of borrowings | E35: 0
A36: MSR | B36: [-] Member shares redeemed | E36: 0
A37: MSI | B37: [+] Member shares issued | E37: 0
B38: Net cash flows from financing activities | E38: =SUM(E35:E37) -> 0
B40: Net increase (decrease) in cash and cash equivalents before effect of exchange rate changes | E40: =SUM(E25,E32,E38) -> 0
A42: OCCE | B42: Opening cash and cash equivalents | E42: =E46 -> 0
A43: MCCE | B43: Movement in cash and cash equivalents | E43: =E40 -> 0
A44: FED | B44: Foreign exchange differences | E44: 0
B45: Closing cash and cash equivalents (calculated) | D45: 49 | E45: =SUM(E42:E44) -> 0
B46: Cash and cash equivalents at beginning of period | E46: =SUM('Statement of Financial Position'!D18:D19) -> 0
B47: Cash and cash equivalents at end of period | E47: =SUM('Statement of Financial Position'!E18:E19) -> 0
...

Sheet Notes of Financial Statement
A1: Identifying information of no-profit
A2: Company name and legal form | B2: ='General information'!B2 -> No-ProfitName LegalForm
A3: The domicile | B3: ='General information'!B3 -> Address 1234, Country
A4: Start period | B4: ='General information'!B8 -> 45292
A5: End period | B5: ='General information'!B9 -> 45657
A6: Notes of Financial Statement
A9: Significant accounting policies
A30: Note nr. | B30: Non-current assets | C30: Amount | D30: Notes
A31: 1 | B31: Investment in associate | C31: ='Statement of Financial Position'!E11 -> 0
A32: 2 | B32: Property, plant and equipment
A33: 2.1 | B33: Land | C33: 0
A34: 2.2 | B34: Buildings | C34: 0
A35: 2.3 | B35: Machinery | C35: 0
A36: 2.4 | B36: Ships | C36: 0
A37: 2.5 | B37: Aircraft | C37: 0
A38: 2.6 | B38: Motor vehicles | C38: 0
A39: 2.7 | B39: Fixtures and fittings | C39: 0
A40: 2.8 | B40: Office equipment | C40: 0
A41: 2.9 | B41: Bearer plants | C41: 0
A42: 2.10 | B42: Tangible exploration and evaluation assets | C42: 0
A43: 2.11 | B43: Mining assets | C43: 0
A44: 2.12 | B44: Oil and gas assets | C44: 0
A45: 2.13 | B45: Construction in progress | C45: 0
A46: 2.14 | B46: Owner-occupied property measured using investment property fair value model | C46: 0
A47: 2.15 | B47: Other property, plant and equipment | C47: 0
B48: Total property, plant and equipment | C48: =SUM(C33:C47) -> 0
A49: 3 | B49: Intangibile assets | C49: ='Statement of Financial Position'!E13 -> 0
A50: 4 | B50: Deferred tax asset | C50: ='Statement of Financial Position'!E14 -> 0
B51: Total non-current assets | C51: =SUM(C31,C48:C50) -> 0
A53: Note nr. | B53: Current assets | C53: Amount | D53: Notes
A54: 5 | B54: Cash | C54: ='Statement of Financial Position'!E18 -> 0
A55: 6 | B55: Bank | C55: ='Statement of Financial Position'!E19 -> 0
A56: 7 | B56: Receivables | C56: ='Statement of Financial Position'!E20 -> 0
A57: 8 | B57: Inventories | C57: ='Statement of Financial Position'!E21 -> 0
B58: Total current assets | C58: =SUM(C54:C57) -> 0
A60: Note nr. | B60: Net assets | C60: Amount | D60: Notes
A61: 9 | B61: Restricted Funds Project 1 | C61: ='Statement of Financial Position'!E27 -> 0
A62: 10 | B62: Restricted Funds Project 2 | C62: ='Statement of Financial Position'!E28 -> 0
A63: 11 | B63: Restricted Funds Project 3 | C63: ='Statement of Financial Position'!E29 -> 0
A64: 12 | B64: Funds without restrictions | C64: ='Statement of Financial Position'!E30 -> 0
...

Sheet Notes of Income Statement
A1: Identifying information of no-profit
A2: Company name and legal form | B2: ='General information'!B2 -> No-ProfitName LegalForm
A3: The domicile | B3: ='General information'!B3 -> Address 1234, Country
A4: Start period | B4: ='General information'!B8 -> 45292
A5: End period | B5: ='General information'!B9 -> 45657
A6: Notes of Statement of Income and Expenses
A9: Note nr. | B9: Income | C9: Amount | D9: Notes
A10: 25 | B10: [+] Grants and donations unrestricted | C10: ='Statement of Income & Expenses'!E10 -> 0
A11: 26 | B11: [+] Grants and donations restricted Project 1 | C11: ='Statement of Income & Expenses'!E11 -> 0
A12: 27 | B12: [+] Grants and donations restricted Project 2 | C12: ='Statement of Income & Expenses'!E12 -> 0
A13: 28 | B13: [+] Grants and donations restricted Project 3 | C13: ='Statement of Income & Expenses'!E13 -> 0
A14: 29 | B14: [+] Government grants unrestricted | C14: ='Statement of Income & Expenses'!E14 -> 0
A15: 30 | B15: [+] Government grants restricted | C15: ='Statement of Income & Expenses'!E15 -> 0
A16: 31 | B16: [+] Grants for and donations of non‑current assets | C16: ='Statement of Income & Expenses'!E16 -> 0
A17: 32 | B17: [+] Sales of services and goods | C17: ='Statement of Income & Expenses'!E17 -> 0
A18: 33 | B18: [+] Interest income | C18: ='Statement of Income & Expenses'!E18 -> 0
A19: 34 | B19: [+] Other income | C19: ='Statement of Income & Expenses'!E19 -> 0
B20: Total income | C20: =SUM(C10:C19) -> 0
A22: Note nr. | B22: Expenses | C22: Amount | D22: Notes
A23: 35 | B23: [-] Expenses Project 1 | C23: ='Statement of Income & Expenses'!E23 -> 0
A24: 36 | B24: [-] Expenses Project 2 | C24: ='Statement of Income & Expenses'!E24 -> 0
A25: 37 | B25: [-] Expenses Project 3 | C25: ='Statement of Income & Expenses'!E25 -> 0
A26: 38 | B26: [-] Operating Expenses | C26: ='Statement of Income & Expenses'!E26 -> 0
A27: 39 | B27: [-] Depreciation and amortisation expenses | C27: ='Statement of Income & Expenses'!E27 -> 0
A28: 40 | B28: [-] Impairment expenses | C28: ='Statement of Income & Expenses'!E28 -> 0
A29: 41 | B29: [-] Interest expenses | C29: ='Statement of Income & Expenses'!E29 -> 0
A30: 42 | B30: [-] Other expenses | C30: ='Statement of Income & Expenses'!E30 -> 0
B31: Total expenses | C31: =SUM(C23:C30) -> 0
A33: Note nr. | B33: Other gains and losses | C33: Amount | D33: Notes
A34: 43 | B34: [+/-] Share of surplus of associates | C34: ='Statement of Income & Expenses'!E34 -> 0
A35: 44 | B35: [+/-] Gain or loss on disposal of assets | C35: ='Statement of Income & Expenses'!E35 -> 0
A36: 45 | B36: [+/-] Unrealised gains or losses on foreign exchange differences | C36: ='Statement of Income & Expenses'!E36 -> 0
A37: 46 | B37: [+/-] Defined benefit plans | C37: ='Statement of Income & Expenses'!E37 -> 0
A38: 47 | B38: [+/-] Financial instruments | C38: ='Statement of Income & Expenses'!E38 -> 0
A39: 48 | B39: [+/-] Investment property | C39: ='Statement of Income & Expenses'!E39 -> 0
B40: Surplus or deficit for the period | C40: =SUM(C20,C31,C34:C39) -> 0

Sheet Notes of Cash flows statement
A1: Identifying information of no-profit
A2: Company name and legal form | B2: ='General information'!B2 -> No-ProfitName LegalForm
A3: The domicile | B3: ='General information'!B3 -> Address 1234, Country
A4: Start period | B4: ='General information'!B8 -> 45292
A5: End period | B5: ='General information'!B9 -> 45657
A6: Notes to the Statement of Cash Flows
A9: Note nr. | B9: Cash and cash equivalents reconciliation | C9: Amount | D9: Notes
B10: Opening cash and cash equivalents | C10: ='Cash Flows Statement - indirect'!E46 -> 0
B11: Cash movement before exchange effects | C11: ='Cash Flows Statement - indirect'!E40 -> 0
B12: Foreign exchange differences | C12: ='Cash Flows Statement - indirect'!E44 -> 0
A13: 49 | B13: Closing cash and cash equivalents | C13: =SUM(C10:C12) -> 0
A15: Note nr. | B15: Explanation of investing and financing transactions not requiring use of cash or cash equivalents | C15: Amount | D15: Notes
C16: 0
C17: 0
C18: 0
A19: 50 | B19: Total non-cash investing and financing transactions | C19: =SUM(C16:C18) -> 0
A21: Note nr. | B21: Description of acquisition of assets by assuming directly related liabilities or means of finance lease | C21: Amount | D21: Notes
C22: 0
C23: 0
C24: 0
A25: 51 | B25: Total non-cash asset acquisitions through liabilities or leases | C25: =SUM(C22:C24) -> 0
A27: Note nr. | B27: Acquisition of entity through issue of equity claims | C27: Amount | D27: Notes
C28: 0
C29: 0
C30: 0
A31: 52 | B31: Total acquisition of entity through equity claims | C31: =SUM(C28:C30) -> 0
A33: Note nr. | B33: Conversion of debt to equity claims | C33: Amount | D33: Notes
C34: 0
C35: 0
C36: 0
A37: 53 | B37: Total conversion of debt to equity claims | C37: =SUM(C34:C36) -> 0
A39: Note nr. | B39: Commentary by management on significant cash and cash equivalent balances held by entity that are not available for use by group | C39: Amount | D39: Notes
C40: 0
C41: 0
C42: 0
A43: 54 | B43: Total Commentary by management on significant cash and cash equivalent balances held by entity that are not available for use by group | C43: =SUM(C40:C42) -> 0

Sheet Additional INPAS Notes
A1: ADDITIONAL EXPLANATORY NOTES | INPAS 2025
A2: Complete the yellow cells below. Explain only material matters that apply to your organisation; use amounts or references from Banana Accounting where available.
A3: This sheet complements the three existing numerical notes sheets. Prior-year figures and fund movement reports can be supplied directly by your accounting software; do not duplicate them here.
A5: Reporting organisation | B5: ='General information'!B2 -> No-ProfitName LegalForm | D5: B1.10
A6: Reporting dates (start / end) | B6: ='General information'!B8 -> 45292 | C6: ='General information'!B9 -> 45657 | D6: B1.10
A7: Presentation currency | B7: ='General information'!B21 -> EUR | C7: Rounding applied (units / thousands, etc.)
A8: Important: do not enter an unrestricted INPAS compliance claim unless the entire applicable Standard has been followed. If first-time adoption applies, use the appropriate transition disclosure.
A10: 1. PREPARATION AND ACCOUNTING POLICIES
A11: TOPIC | B11: WHAT SHOULD BE EXPLAINED | C11: WRITE YOUR NOTE OR REFER TO A REPORT | D11: INPAS
A12: Basis and level of INPAS compliance | B12: State the reporting basis and whether full INPAS compliance, financial-statements-only transition compliance, or neither is claimed. Only make a compliance statement if all relevant conditions are fulfilled. | D12: B1.3, B1.20; Z1.5
A13: Material accounting policies | B13: Explain the policies important to your figures: when income and expenses are recognised (accrual), valuation, depreciation, foreign-currency treatment, and other relevant methods. Do not repeat immaterial policies. | D13: B6.2, B6.5
A14: Significant judgements and estimates | B14: Describe judgements with a major accounting effect and important estimates that could materially change asset or liability values next year. Give relevant amounts or refer to the accounting report. | D14: B6.6-B6.7
A15: Going concern - if uncertain | B15: Describe major uncertainties about the ability to continue activities. If the accounts are not prepared on a going-concern basis, explain why and what basis was used. | D15: B1.4-B1.5
A16: First-time adoption - if relevant | B16: In the first INPAS report, explain the transition, material accounting policy changes and the required reconciliations; refer to the transition schedules prepared from the accounting software. | D16: Z1.3-Z1.18
A18: 2. GRANTS, DONATIONS AND FUNDS
A19: Grants and donation revenue analysis | B19: Disclose revenue WITH and WITHOUT delivery obligations. For each group show how much is cash, donated goods and donated services. Enter amounts here or clearly cite the corresponding report. | D19: C1.106
A20: Income without delivery obligations | B20: Describe when grants/donations become receivable and are recognised. Disclose opening and closing balances of related receivables unless already reported elsewhere. | D20: C1.58-C1.60; C1.108
A21: Grants WITH delivery obligations | B21: Describe what must be delivered, timing, significant payment terms, how income is recognised, unfulfilled obligations where required, and opening/closing receivables and delivery-obligation assets/liabilities unless otherwise reported. | D21: C1.110-C1.114
A22: Donated goods and services | B22: Explain donated goods or volunteer services not recognised when received, why they were not recognised, which permitted exception was used (if any), and their significance to the organisation. | D22: C1.62-C1.68; C1.107
A23: Explanation of individual funds | B23: Refer to the detailed fund movement report from Banana Accounting. If that report does not include purposes of each fund, reasons for transfers, any restricted-fund shortfalls or plans for designated funds, explain them here. | D23: B8.26-B8.27
A25: 3. EXPENSES AND OTHER RELEVANT DISCLOSURES
A26: Expenses and cost allocation | B26: If expenses are shown by function or in mixed categories, explain the choice, which expense types each function includes, and how shared costs are allocated. Disclose volunteer benefits and material unusual losses where relevant. | D26: D1.12-D1.15
A27: Assets, liabilities and other commitments | B27: Describe significant asset valuations, depreciation/impairment, provisions, uncertain liabilities, financial-instrument risks, borrowing terms or leases that are applicable and not already detailed in existing notes. | D27: E2, E5; D5-D6; F1
A28: Related parties and governing body | B28: Explain related-party transactions and outstanding balances (if any), key management remuneration, and whether governing-body members were paid benefits or compensation; state explicitly when none were paid. | D28: H1.7-H1.14
A29: Restricted or unavailable cash | B29: If material bank/cash balances cannot be freely used, describe the amount and reason (such as donor restrictions). Refer to the existing Notes of Cash flows statement for the figures. | D29: B5.25
A30: Approval and events after year-end | B30: State the date and person/body authorising the financial statements. If major events occurred afterwards but before authorisation, describe them and their estimated financial effect, if relevant. | D30: H3.9-H3.10
A31: Other relevant disclosures | B31: Add any other material information required by the INPAS sections applicable to the organisation, not included in the accounting reports or other notes. In particular, explain unusual events or material policy changes. | D31: B6.1-B6.3
A33: HOW TO COMPLETE
A34: Write an explanation or a reference to a specific accounting report in the yellow field. Where not applicable, mark N/A and omit that item from the published notes. Review all disclosures relevant to the actual transactions.
A35: Source: INPAS 2025, The Standard (https://www.inprf.org). Paragraph references are shown on the right. This worksheet is a preparation aid; it is not, by itself, a statement of full INPAS compliance.
